Workbook

Sheet Summary
A1: NIS2 Readiness Review
A2: Kertvár Food Distribution Kft. (fictional company)
A3: This is a readiness review for portfolio purposes, not a NIS2 audit. Audits are a regulated activity in Hungary (SZTFH).
A5: Scope
A6: Entity | B6: Kertvár Food Distribution Kft. — food wholesale distribution, 140 staff, ~€28M revenue
A7: NIS2 classification | B7: Important entity (medium-sized, Annex II food sector; Hungarian Act LXIX of 2024, Annex 2)
A8: Assessed against | B8: NIS2 Art. 20 (management) and Art. 21(2)(a)–(j); incident reporting per Art. 23
A9: Method | B9: 46-question self-assessment, scored per area; gaps ranked by importance; key risks in a risk register
A11: Results
A12: Overall readiness score | B12: =Scores!G15 -> 0.26086957
A13: Overall rating | B13: =Scores!H15 -> Weak
A14: High-priority gaps | B14: =Scores!I15 -> 22
A15: High-rated risks | B15: =COUNTIF('Risk register'!I5:I16,"High") -> 3
A16: Weakest area | B16: =INDEX(Scores!B4:B14,MATCH(MIN(Scores!G4:G14),Scores!G4:G14,0)) -> Effectiveness assessment
A17: Strongest area | B17: =INDEX(Scores!B4:B14,MATCH(MAX(Scores!G4:G14),Scores!G4:G14,0)) -> Cryptography and encryption
A19: Key findings
A20: 1 | B20: Backups are not protected against ransomware: the only copy sits next to the server, online, and has never been restore-tested.
A21: 2 | B21: MFA is enabled on only 2 accounts; phishing regularly reaches staff, who have had no training.
A22: 3 | B22: There is no incident procedure, and nobody knows the NIS2 reporting deadlines (24h early warning, 72h notification).
A23: 4 | B23: Suppliers have permanent, password-only remote access, and contracts have no security clauses.
A24: 5 | B24: Management has not approved security measures or completed training, which NIS2 Art. 20 requires.
A26: First 90 days — recommended actions
A27: 1. Within 2 weeks | B27: Enable MFA for all Microsoft 365 users and the VPN; change the cold store default password.
A28: 2. Within 1 month | B28: Add an off-site/offline backup copy and run the first restore test.
A29: 3. Within 1 month | B29: Write a 1–2 page incident procedure naming who reports to the CSIRT and by when.
A30: 4. Within 2 months | B30: Switch supplier remote access to on-request, with MFA and logging.
A31: 5. Within 3 months | B31: Management approves a security policy and attends training; staff awareness training starts.
A33: Sheets in this workbook | B33: Questionnaire · Scores · Gaps · Risk register · Company · Method

Sheet Questionnaire
A1: Questionnaire — answer each question with Yes / Partial / No / N/A
A2: Edit only the yellow cells (Answer, Weight). Points: Yes = 2, Partial = 1, No = 0, N/A = excluded. Gap score = (2 − points) × weight.
A4: ID | B4: Area | C4: Area name | D4: Question | E4: Answer | F4: Weight (1-3) | G4: Points | H4: Gap score | I4: Priority | J4: Finding at Kertvár | K4: Recommendation
A5: M1 | B5: M | C5: Management responsibility | D5: Has management formally approved the cybersecurity risk-management measures? | E5: No | F5: 3 | G5: =IF(E5="Yes",2,IF(E5="Partial",1,IF(E5="No",0,""))) -> 0 | H5: =IF(G5="",0,(2-G5)*F5) -> 6 | I5: =IF(H5>=4,"High",IF(H5>=2,"Medium",IF(H5>=1,"Low","None"))) -> High | J5: No approved measures; security is handled ad hoc by IT. | K5: Managing director to approve a security policy and measures plan in writing.
A6: M2 | B6: M | C6: Management responsibility | D6: Has management completed cybersecurity training? | E6: No | F6: 2 | G6: =IF(E6="Yes",2,IF(E6="Partial",1,IF(E6="No",0,""))) -> 0 | H6: =IF(G6="",0,(2-G6)*F6) -> 4 | I6: =IF(H6>=4,"High",IF(H6>=2,"Medium",IF(H6>=1,"Low","None"))) -> High | J6: Managing director and finance manager have had no training. | K6: Book a half-day management cybersecurity training session.
A7: M3 | B7: M | C7: Management responsibility | D7: Is a named person responsible for cybersecurity? | E7: Partial | F7: 2 | G7: =IF(E7="Yes",2,IF(E7="Partial",1,IF(E7="No",0,""))) -> 1 | H7: =IF(G7="",0,(2-G7)*F7) -> 2 | I7: =IF(H7>=4,"High",IF(H7>=2,"Medium",IF(H7>=1,"Low","None"))) -> Medium | J7: IT administrator does it informally; finance manager covers 'compliance' part-time. | K7: Formally name a security lead with time allocated.
A8: M4 | B8: M | C8: Management responsibility | D8: Has the company confirmed its NIS2 status and registered with the authority? | E8: Yes | F8: 1 | G8: =IF(E8="Yes",2,IF(E8="Partial",1,IF(E8="No",0,""))) -> 2 | H8: =IF(G8="",0,(2-G8)*F8) -> 0 | I8: =IF(H8>=4,"High",IF(H8>=2,"Medium",IF(H8>=1,"Low","None"))) -> None | J8: Registered with SZTFH as an important entity. | K8: Keep registration details up to date.
A9: a1 | B9: a | C9: Risk analysis and security policies | D9: Is there a written information security policy, approved and shared with staff? | E9: No | F9: 3 | G9: =IF(E9="Yes",2,IF(E9="Partial",1,IF(E9="No",0,""))) -> 0 | H9: =IF(G9="",0,(2-G9)*F9) -> 6 | I9: =IF(H9>=4,"High",IF(H9>=2,"Medium",IF(H9>=1,"Low","None"))) -> High | J9: No written policy exists. | K9: Write a short security policy covering the Art. 21 areas.
A10: a2 | B10: a | C10: Risk analysis and security policies | D10: Has a documented IT risk assessment been done in the last 12 months? | E10: No | F10: 3 | G10: =IF(E10="Yes",2,IF(E10="Partial",1,IF(E10="No",0,""))) -> 0 | H10: =IF(G10="",0,(2-G10)*F10) -> 6 | I10: =IF(H10>=4,"High",IF(H10>=2,"Medium",IF(H10>=1,"Low","None"))) -> High | J10: Never done. | K10: Run a yearly risk assessment and keep the risk register up to date.
A11: a3 | B11: a | C11: Risk analysis and security policies | D11: Are critical systems identified with their business impact (ERP, cold store, web shop)? | E11: Partial | F11: 2 | G11: =IF(E11="Yes",2,IF(E11="Partial",1,IF(E11="No",0,""))) -> 1 | H11: =IF(G11="",0,(2-G11)*F11) -> 2 | I11: =IF(H11>=4,"High",IF(H11>=2,"Medium",IF(H11>=1,"Low","None"))) -> Medium | J11: Everyone knows SAP is critical, but nothing is written down. | K11: List critical systems with impact and maximum tolerable downtime.
A12: a4 | B12: a | C12: Risk analysis and security policies | D12: Are security policies reviewed at least yearly? | E12: No | F12: 1 | G12: =IF(E12="Yes",2,IF(E12="Partial",1,IF(E12="No",0,""))) -> 0 | H12: =IF(G12="",0,(2-G12)*F12) -> 2 | I12: =IF(H12>=4,"High",IF(H12>=2,"Medium",IF(H12>=1,"Low","None"))) -> Medium | J12: No policies to review. | K12: Set a yearly review date once the policy exists.
A13: b1 | B13: b | C13: Incident handling and reporting | D13: Is there a written incident response procedure? | E13: No | F13: 3 | G13: =IF(E13="Yes",2,IF(E13="Partial",1,IF(E13="No",0,""))) -> 0 | H13: =IF(G13="",0,(2-G13)*F13) -> 6 | I13: =IF(H13>=4,"High",IF(H13>=2,"Medium",IF(H13>=1,"Low","None"))) -> High | J13: No procedure; staff would call the IT admin's mobile. | K13: Write a 1-2 page incident procedure with roles and contacts.
A14: b2 | B14: b | C14: Incident handling and reporting | D14: Do staff know how and to whom to report a suspicious event? | E14: Partial | F14: 2 | G14: =IF(E14="Yes",2,IF(E14="Partial",1,IF(E14="No",0,""))) -> 1 | H14: =IF(G14="",0,(2-G14)*F14) -> 2 | I14: =IF(H14>=4,"High",IF(H14>=2,"Medium",IF(H14>=1,"Low","None"))) -> Medium | J14: Office staff call IT; warehouse staff and drivers don't know. | K14: Put a one-line reporting rule on posters and in onboarding.
A15: b3 | B15: b | C15: Incident handling and reporting | D15: Is there a process to report significant incidents to the national CSIRT (24h early warning, 72h notification)? | E15: No | F15: 3 | G15: =IF(E15="Yes",2,IF(E15="Partial",1,IF(E15="No",0,""))) -> 0 | H15: =IF(G15="",0,(2-G15)*F15) -> 6 | I15: =IF(H15>=4,"High",IF(H15>=2,"Medium",IF(H15>=1,"Low","None"))) -> High | J15: Nobody knows the deadlines or who would report. | K15: Name who reports, add CSIRT contacts and deadlines to the procedure.
A16: b4 | B16: b | C16: Incident handling and reporting | D16: Are logs (firewall, Microsoft 365, server) kept long enough to investigate an incident? | E16: Partial | F16: 2 | G16: =IF(E16="Yes",2,IF(E16="Partial",1,IF(E16="No",0,""))) -> 1 | H16: =IF(G16="",0,(2-G16)*F16) -> 2 | I16: =IF(H16>=4,"High",IF(H16>=2,"Medium",IF(H16>=1,"Low","None"))) -> Medium | J16: M365 default retention only; server and firewall logs overwrite after a few days. | K16: Keep key logs for at least 90 days.
... A50: j4 | B50: j | C50: MFA and secure communications | D50: Is sensitive data shared securely (e.g. with the payroll bureau)? | E50: Partial | F50: 2 | G50: =IF(E50="Yes",2,IF(E50="Partial",1,IF(E50="No",0,""))) -> 1 | H50: =IF(G50="",0,(2-G50)*F50) -> 2 | I50: =IF(H50>=4,"High",IF(H50>=2,"Medium",IF(H50>=1,"Low","None"))) -> Medium | J50: Payroll files sometimes sent by plain email. | K50: Use the payroll bureau's secure portal only.

Sheet Scores
A1: Readiness score per area
A3: Area | B3: Area name | C3: NIS2 reference | D3: Questions | E3: Points achieved | F3: Points possible | G3: Score | H3: Rating | I3: High gaps
A4: M | B4: Management responsibility | C4: Art. 20 | D4: =COUNTIF(Questionnaire!$B$5:$B$50,A4) -> 4 | E4: =SUMIF(Questionnaire!$B$5:$B$50,A4,Questionnaire!$G$5:$G$50) -> 3 | F4: =2*(D4-COUNTIFS(Questionnaire!$B$5:$B$50,A4,Questionnaire!$E$5:$E$50,"N/A")) -> 8 | G4: =IF(F4=0,0,E4/F4) -> 0.375 | H4: =IF(G4>=0.75,"Good",IF(G4>=0.5,"Partial","Weak")) -> Weak | I4: =COUNTIFS(Questionnaire!$B$5:$B$50,A4,Questionnaire!$I$5:$I$50,"High") -> 2
A5: a | B5: Risk analysis and security policies | C5: Art. 21(2)(a) | D5: =COUNTIF(Questionnaire!$B$5:$B$50,A5) -> 4 | E5: =SUMIF(Questionnaire!$B$5:$B$50,A5,Questionnaire!$G$5:$G$50) -> 1 | F5: =2*(D5-COUNTIFS(Questionnaire!$B$5:$B$50,A5,Questionnaire!$E$5:$E$50,"N/A")) -> 8 | G5: =IF(F5=0,0,E5/F5) -> 0.125 | H5: =IF(G5>=0.75,"Good",IF(G5>=0.5,"Partial","Weak")) -> Weak | I5: =COUNTIFS(Questionnaire!$B$5:$B$50,A5,Questionnaire!$I$5:$I$50,"High") -> 2
A6: b | B6: Incident handling and reporting | C6: Art. 21(2)(b), Art. 23 | D6: =COUNTIF(Questionnaire!$B$5:$B$50,A6) -> 5 | E6: =SUMIF(Questionnaire!$B$5:$B$50,A6,Questionnaire!$G$5:$G$50) -> 2 | F6: =2*(D6-COUNTIFS(Questionnaire!$B$5:$B$50,A6,Questionnaire!$E$5:$E$50,"N/A")) -> 10 | G6: =IF(F6=0,0,E6/F6) -> 0.2 | H6: =IF(G6>=0.75,"Good",IF(G6>=0.5,"Partial","Weak")) -> Weak | I6: =COUNTIFS(Questionnaire!$B$5:$B$50,A6,Questionnaire!$I$5:$I$50,"High") -> 2
A7: c | B7: Business continuity and backups | C7: Art. 21(2)(c) | D7: =COUNTIF(Questionnaire!$B$5:$B$50,A7) -> 5 | E7: =SUMIF(Questionnaire!$B$5:$B$50,A7,Questionnaire!$G$5:$G$50) -> 3 | F7: =2*(D7-COUNTIFS(Questionnaire!$B$5:$B$50,A7,Questionnaire!$E$5:$E$50,"N/A")) -> 10 | G7: =IF(F7=0,0,E7/F7) -> 0.3 | H7: =IF(G7>=0.75,"Good",IF(G7>=0.5,"Partial","Weak")) -> Weak | I7: =COUNTIFS(Questionnaire!$B$5:$B$50,A7,Questionnaire!$I$5:$I$50,"High") -> 3
A8: d | B8: Supply chain security | C8: Art. 21(2)(d) | D8: =COUNTIF(Questionnaire!$B$5:$B$50,A8) -> 4 | E8: =SUMIF(Questionnaire!$B$5:$B$50,A8,Questionnaire!$G$5:$G$50) -> 1 | F8: =2*(D8-COUNTIFS(Questionnaire!$B$5:$B$50,A8,Questionnaire!$E$5:$E$50,"N/A")) -> 8 | G8: =IF(F8=0,0,E8/F8) -> 0.125 | H8: =IF(G8>=0.75,"Good",IF(G8>=0.5,"Partial","Weak")) -> Weak | I8: =COUNTIFS(Questionnaire!$B$5:$B$50,A8,Questionnaire!$I$5:$I$50,"High") -> 3
A9: e | B9: Secure acquisition, development and maintenance | C9: Art. 21(2)(e) | D9: =COUNTIF(Questionnaire!$B$5:$B$50,A9) -> 4 | E9: =SUMIF(Questionnaire!$B$5:$B$50,A9,Questionnaire!$G$5:$G$50) -> 2 | F9: =2*(D9-COUNTIFS(Questionnaire!$B$5:$B$50,A9,Questionnaire!$E$5:$E$50,"N/A")) -> 8 | G9: =IF(F9=0,0,E9/F9) -> 0.25 | H9: =IF(G9>=0.75,"Good",IF(G9>=0.5,"Partial","Weak")) -> Weak | I9: =COUNTIFS(Questionnaire!$B$5:$B$50,A9,Questionnaire!$I$5:$I$50,"High") -> 1
A10: f | B10: Effectiveness assessment | C10: Art. 21(2)(f) | D10: =COUNTIF(Questionnaire!$B$5:$B$50,A10) -> 3 | E10: =SUMIF(Questionnaire!$B$5:$B$50,A10,Questionnaire!$G$5:$G$50) -> 0 | F10: =2*(D10-COUNTIFS(Questionnaire!$B$5:$B$50,A10,Questionnaire!$E$5:$E$50,"N/A")) -> 6 | G10: =IF(F10=0,0,E10/F10) -> 0 | H10: =IF(G10>=0.75,"Good",IF(G10>=0.5,"Partial","Weak")) -> Weak | I10: =COUNTIFS(Questionnaire!$B$5:$B$50,A10,Questionnaire!$I$5:$I$50,"High") -> 2
A11: g | B11: Cyber hygiene and training | C11: Art. 21(2)(g) | D11: =COUNTIF(Questionnaire!$B$5:$B$50,A11) -> 4 | E11: =SUMIF(Questionnaire!$B$5:$B$50,A11,Questionnaire!$G$5:$G$50) -> 3 | F11: =2*(D11-COUNTIFS(Questionnaire!$B$5:$B$50,A11,Questionnaire!$E$5:$E$50,"N/A")) -> 8 | G11: =IF(F11=0,0,E11/F11) -> 0.375 | H11: =IF(G11>=0.75,"Good",IF(G11>=0.5,"Partial","Weak")) -> Weak | I11: =COUNTIFS(Questionnaire!$B$5:$B$50,A11,Questionnaire!$I$5:$I$50,"High") -> 2
A12: h | B12: Cryptography and encryption | C12: Art. 21(2)(h) | D12: =COUNTIF(Questionnaire!$B$5:$B$50,A12) -> 4 | E12: =SUMIF(Questionnaire!$B$5:$B$50,A12,Questionnaire!$G$5:$G$50) -> 5 | F12: =2*(D12-COUNTIFS(Questionnaire!$B$5:$B$50,A12,Questionnaire!$E$5:$E$50,"N/A")) -> 8 | G12: =IF(F12=0,0,E12/F12) -> 0.625 | H12: =IF(G12>=0.75,"Good",IF(G12>=0.5,"Partial","Weak")) -> Partial | I12: =COUNTIFS(Questionnaire!$B$5:$B$50,A12,Questionnaire!$I$5:$I$50,"High") -> 1
A13: i | B13: HR security, access control and assets | C13: Art. 21(2)(i) | D13: =COUNTIF(Questionnaire!$B$5:$B$50,A13) -> 5 | E13: =SUMIF(Questionnaire!$B$5:$B$50,A13,Questionnaire!$G$5:$G$50) -> 2 | F13: =2*(D13-COUNTIFS(Questionnaire!$B$5:$B$50,A13,Questionnaire!$E$5:$E$50,"N/A")) -> 10 | G13: =IF(F13=0,0,E13/F13) -> 0.2 | H13: =IF(G13>=0.75,"Good",IF(G13>=0.5,"Partial","Weak")) -> Weak | I13: =COUNTIFS(Questionnaire!$B$5:$B$50,A13,Questionnaire!$I$5:$I$50,"High") -> 2
A14: j | B14: MFA and secure communications | C14: Art. 21(2)(j) | D14: =COUNTIF(Questionnaire!$B$5:$B$50,A14) -> 4 | E14: =SUMIF(Questionnaire!$B$5:$B$50,A14,Questionnaire!$G$5:$G$50) -> 2 | F14: =2*(D14-COUNTIFS(Questionnaire!$B$5:$B$50,A14,Questionnaire!$E$5:$E$50,"N/A")) -> 8 | G14: =IF(F14=0,0,E14/F14) -> 0.25 | H14: =IF(G14>=0.75,"Good",IF(G14>=0.5,"Partial","Weak")) -> Weak | I14: =COUNTIFS(Questionnaire!$B$5:$B$50,A14,Questionnaire!$I$5:$I$50,"High") -> 2
A15: Overall | D15: =SUM(D4:D14) -> 46 | E15: =SUM(E4:E14) -> 24 | F15: =SUM(F4:F14) -> 92 | G15: =IF(F15=0,0,E15/F15) -> 0.26086957 | H15: =IF(G15>=0.75,"Good",IF(G15>=0.5,"Partial","Weak")) -> Weak | I15: =SUM(I4:I14) -> 22
A17: Rating: Good ≥ 75% · Partial 50–74% · Weak < 50%

Sheet Gaps
A1: Gap report — ranked by gap score (importance × how far from 'Yes')
A2: Order reflects the assessed answers. Cells link to the Questionnaire, so values update if answers change; re-sort by Gap score if needed.
A4: Rank | B4: ID | C4: Area name | D4: Question | E4: Answer | F4: Gap score | G4: Priority | H4: Recommendation
A5: 1 | B5: =Questionnaire!A5 -> M1 | C5: =Questionnaire!C5 -> Management responsibility | D5: =Questionnaire!D5 -> Has management formally approved the cybersecurity risk-management measures? | E5: =Questionnaire!E5 -> No | F5: =Questionnaire!H5 -> 6 | G5: =Questionnaire!I5 -> High | H5: =Questionnaire!K5 -> Managing director to approve a security policy and measures plan in writing.
A6: 2 | B6: =Questionnaire!A9 -> a1 | C6: =Questionnaire!C9 -> Risk analysis and security policies | D6: =Questionnaire!D9 -> Is there a written information security policy, approved and shared with staff? | E6: =Questionnaire!E9 -> No | F6: =Questionnaire!H9 -> 6 | G6: =Questionnaire!I9 -> High | H6: =Questionnaire!K9 -> Write a short security policy covering the Art. 21 areas.
A7: 3 | B7: =Questionnaire!A10 -> a2 | C7: =Questionnaire!C10 -> Risk analysis and security policies | D7: =Questionnaire!D10 -> Has a documented IT risk assessment been done in the last 12 months? | E7: =Questionnaire!E10 -> No | F7: =Questionnaire!H10 -> 6 | G7: =Questionnaire!I10 -> High | H7: =Questionnaire!K10 -> Run a yearly risk assessment and keep the risk register up to date.
A8: 4 | B8: =Questionnaire!A13 -> b1 | C8: =Questionnaire!C13 -> Incident handling and reporting | D8: =Questionnaire!D13 -> Is there a written incident response procedure? | E8: =Questionnaire!E13 -> No | F8: =Questionnaire!H13 -> 6 | G8: =Questionnaire!I13 -> High | H8: =Questionnaire!K13 -> Write a 1-2 page incident procedure with roles and contacts.
A9: 5 | B9: =Questionnaire!A15 -> b3 | C9: =Questionnaire!C15 -> Incident handling and reporting | D9: =Questionnaire!D15 -> Is there a process to report significant incidents to the national CSIRT (24h early warning, 72h notification)? | E9: =Questionnaire!E15 -> No | F9: =Questionnaire!H15 -> 6 | G9: =Questionnaire!I15 -> High | H9: =Questionnaire!K15 -> Name who reports, add CSIRT contacts and deadlines to the procedure.
A10: 6 | B10: =Questionnaire!A19 -> c2 | C10: =Questionnaire!C19 -> Business continuity and backups | D10: =Questionnaire!D19 -> Is at least one backup copy offline or off-site? | E10: =Questionnaire!E19 -> No | F10: =Questionnaire!H19 -> 6 | G10: =Questionnaire!I19 -> High | H10: =Questionnaire!K19 -> Add an off-site or offline copy (cloud backup or rotated disk).
A11: 7 | B11: =Questionnaire!A20 -> c3 | C11: =Questionnaire!C20 -> Business continuity and backups | D11: =Questionnaire!D20 -> Has a restore been tested in the last 6 months? | E11: =Questionnaire!E20 -> No | F11: =Questionnaire!H20 -> 6 | G11: =Questionnaire!I20 -> High | H11: =Questionnaire!K20 -> Test a full restore of the ERP every quarter and record the result.
A12: 8 | B12: =Questionnaire!A24 -> d2 | C12: =Questionnaire!C24 -> Supply chain security | D12: =Questionnaire!D24 -> Do supplier contracts include security and incident-notification requirements? | E12: =Questionnaire!E24 -> No | F12: =Questionnaire!H24 -> 6 | G12: =Questionnaire!I24 -> High | H12: =Questionnaire!K24 -> Add security clauses when contracts are renewed.
A13: 9 | B13: =Questionnaire!A25 -> d3 | C13: =Questionnaire!C25 -> Supply chain security | D13: =Questionnaire!D25 -> Is supplier remote access approved, time-limited and logged? | E13: =Questionnaire!E25 -> No | F13: =Questionnaire!H25 -> 6 | G13: =Questionnaire!I25 -> High | H13: =Questionnaire!K25 -> Enable supplier access only on request, with logging.
A14: 10 | B14: =Questionnaire!A29 -> e3 | C14: =Questionnaire!C29 -> Secure acquisition, development and maintenance | D14: =Questionnaire!D29 -> Are default passwords changed on new devices and services? | E14: =Questionnaire!E29 -> No | F14: =Questionnaire!H29 -> 6 | G14: =Questionnaire!I29 -> High | H14: =Questionnaire!K29 -> Change all default passwords; add it to the setup checklist.
A15: 11 | B15: =Questionnaire!A34 -> g1 | C15: =Questionnaire!C34 -> Cyber hygiene and training | D15: =Questionnaire!D34 -> Has all staff had security awareness training in the last 12 months? | E15: =Questionnaire!E34 -> No | F15: =Questionnaire!H34 -> 6 | G15: =Questionnaire!I34 -> High | H15: =Questionnaire!K34 -> Run yearly awareness training, including warehouse staff and drivers.
A16: 12 | B16: =Questionnaire!A35 -> g2 | C16: =Questionnaire!C35 -> Cyber hygiene and training | D16: =Questionnaire!D35 -> Are staff trained to recognise phishing? | E16: =Questionnaire!E35 -> No | F16: =Questionnaire!H35 -> 6 | G16: =Questionnaire!I35 -> High | H16: =Questionnaire!K35 -> Add phishing examples to the training; consider simple phishing tests.
A17: 13 | B17: =Questionnaire!A47 -> j1 | C17: =Questionnaire!C47 -> MFA and secure communications | D17: =Questionnaire!D47 -> Is MFA enabled on all Microsoft 365 accounts? | E17: =Questionnaire!E47 -> No | F17: =Questionnaire!H47 -> 6 | G17: =Questionnaire!I47 -> High | H17: =Questionnaire!K47 -> Enable MFA for all users.
A18: 14 | B18: =Questionnaire!A48 -> j2 | C18: =Questionnaire!C48 -> MFA and secure communications | D18: =Questionnaire!D48 -> Is MFA required for remote access, including suppliers? | E18: =Questionnaire!E48 -> No | F18: =Questionnaire!H48 -> 6 | G18: =Questionnaire!I48 -> High | H18: =Questionnaire!K48 -> Require MFA on the VPN.
A19: 15 | B19: =Questionnaire!A6 -> M2 | C19: =Questionnaire!C6 -> Management responsibility | D19: =Questionnaire!D6 -> Has management completed cybersecurity training? | E19: =Questionnaire!E6 -> No | F19: =Questionnaire!H6 -> 4 | G19: =Questionnaire!I6 -> High | H19: =Questionnaire!K6 -> Book a half-day management cybersecurity training session.
A20: 16 | B20: =Questionnaire!A22 -> c5 | C20: =Questionnaire!C22 -> Business continuity and backups | D20: =Questionnaire!D22 -> Are recovery time targets defined for critical systems? | E20: =Questionnaire!E22 -> No | F20: =Questionnaire!H22 -> 4 | G20: =Questionnaire!I22 -> High | H20: =Questionnaire!K22 -> Agree recovery targets with management (e.g. ERP back within 24h).
A21: 17 | B21: =Questionnaire!A26 -> d4 | C21: =Questionnaire!C26 -> Supply chain security | D21: =Questionnaire!D26 -> Are suppliers' security practices checked before onboarding? | E21: =Questionnaire!E26 -> No | F21: =Questionnaire!H26 -> 4 | G21: =Questionnaire!I26 -> High | H21: =Questionnaire!K26 -> Use a short supplier security questionnaire.
A22: 18 | B22: =Questionnaire!A31 -> f1 | C22: =Questionnaire!C31 -> Effectiveness assessment | D22: =Questionnaire!D31 -> Are security measures checked periodically (internal review or test)? | E22: =Questionnaire!E31 -> No | F22: =Questionnaire!H31 -> 4 | G22: =Questionnaire!I31 -> High | H22: =Questionnaire!K31 -> Do a yearly internal review using this questionnaire.
A23: 19 | B23: =Questionnaire!A32 -> f2 | C23: =Questionnaire!C32 -> Effectiveness assessment | D23: =Questionnaire!D32 -> Has an external vulnerability scan or penetration test been done? | E23: =Questionnaire!E32 -> No | F23: =Questionnaire!H32 -> 4 | G23: =Questionnaire!I32 -> High | H23: =Questionnaire!K32 -> Run an external vulnerability scan of the web shop and firewall.
A24: 20 | B24: =Questionnaire!A41 -> h4 | C24: =Questionnaire!C41 -> Cryptography and encryption | D24: =Questionnaire!D41 -> Are backups encrypted? | E24: =Questionnaire!E41 -> No | F24: =Questionnaire!H41 -> 4 | G24: =Questionnaire!I41 -> High | H24: =Questionnaire!K41 -> Encrypt backups, especially any off-site copy.
A25: 21 | B25: =Questionnaire!A43 -> i2 | C25: =Questionnaire!C43 -> HR security, access control and assets | D25: =Questionnaire!D43 -> Does everyone use their own account (no shared logins)? | E25: =Questionnaire!E43 -> No | F25: =Questionnaire!H43 -> 4 | G25: =Questionnaire!I43 -> High | H25: =Questionnaire!K43 -> Give scanner users individual logins or PINs.
A26: 22 | B26: =Questionnaire!A45 -> i4 | C26: =Questionnaire!C45 -> HR security, access control and assets | D26: =Questionnaire!D45 -> Is there an up-to-date inventory of all devices? | E26: =Questionnaire!E45 -> No | F26: =Questionnaire!H45 -> 4 | G26: =Questionnaire!I45 -> High | H26: =Questionnaire!K45 -> Build a device inventory (PCs, scanners, phones, server, NAS).
A27: 23 | B27: =Questionnaire!A27 -> e1 | C27: =Questionnaire!C27 -> Secure acquisition, development and maintenance | D27: =Questionnaire!D27 -> Are PCs and servers patched regularly (at least monthly)? | E27: =Questionnaire!E27 -> Partial | F27: =Questionnaire!H27 -> 3 | G27: =Questionnaire!I27 -> Medium | H27: =Questionnaire!K27 -> Agree a monthly patch window for the server.
A28: 24 | B28: =Questionnaire!A42 -> i1 | C28: =Questionnaire!C42 -> HR security, access control and assets | D28: =Questionnaire!D42 -> Are leavers' accounts disabled on their last day? | E28: =Questionnaire!E42 -> Partial | F28: =Questionnaire!H42 -> 3 | G28: =Questionnaire!I42 -> Medium | H28: =Questionnaire!K42 -> Add account removal to the HR leaver checklist.
A29: 25 | B29: =Questionnaire!A7 -> M3 | C29: =Questionnaire!C7 -> Management responsibility | D29: =Questionnaire!D7 -> Is a named person responsible for cybersecurity? | E29: =Questionnaire!E7 -> Partial | F29: =Questionnaire!H7 -> 2 | G29: =Questionnaire!I7 -> Medium | H29: =Questionnaire!K7 -> Formally name a security lead with time allocated.
A30: 26 | B30: =Questionnaire!A11 -> a3 | C30: =Questionnaire!C11 -> Risk analysis and security policies | D30: =Questionnaire!D11 -> Are critical systems identified with their business impact (ERP, cold store, web shop)? | E30: =Questionnaire!E11 -> Partial | F30: =Questionnaire!H11 -> 2 | G30: =Questionnaire!I11 -> Medium | H30: =Questionnaire!K11 -> List critical systems with impact and maximum tolerable downtime.
A31: 27 | B31: =Questionnaire!A12 -> a4 | C31: =Questionnaire!C12 -> Risk analysis and security policies | D31: =Questionnaire!D12 -> Are security policies reviewed at least yearly? | E31: =Questionnaire!E12 -> No | F31: =Questionnaire!H12 -> 2 | G31: =Questionnaire!I12 -> Medium | H31: =Questionnaire!K12 -> Set a yearly review date once the policy exists.
A32: 28 | B32: =Questionnaire!A14 -> b2 | C32: =Questionnaire!C14 -> Incident handling and reporting | D32: =Questionnaire!D14 -> Do staff know how and to whom to report a suspicious event? | E32: =Questionnaire!E14 -> Partial | F32: =Questionnaire!H14 -> 2 | G32: =Questionnaire!I14 -> Medium | H32: =Questionnaire!K14 -> Put a one-line reporting rule on posters and in onboarding.
A33: 29 | B33: =Questionnaire!A16 -> b4 | C33: =Questionnaire!C16 -> Incident handling and reporting | D33: =Questionnaire!D16 -> Are logs (firewall, Microsoft 365, server) kept long enough to investigate an incident? | E33: =Questionnaire!E16 -> Partial | F33: =Questionnaire!H16 -> 2 | G33: =Questionnaire!I16 -> Medium | H33: =Questionnaire!K16 -> Keep key logs for at least 90 days.
A34: 30 | B34: =Questionnaire!A17 -> b5 | C34: =Questionnaire!C17 -> Incident handling and reporting | D34: =Questionnaire!D17 -> Is an incident log kept? | E34: =Questionnaire!E17 -> No | F34: =Questionnaire!H17 -> 2 | G34: =Questionnaire!I17 -> Medium | H34: =Questionnaire!K17 -> Start a simple incident log (date, what, impact, action).
A35: 31 | B35: =Questionnaire!A21 -> c4 | C35: =Questionnaire!C21 -> Business continuity and backups | D35: =Questionnaire!D21 -> Is there a continuity plan for losing the ERP or cold store monitoring? | E35: =Questionnaire!E21 -> Partial | F35: =Questionnaire!H21 -> 2 | G35: =Questionnaire!I21 -> Medium | H35: =Questionnaire!K21 -> Write a manual fallback for orders and deliveries.
A36: 32 | B36: =Questionnaire!A23 -> d1 | C36: =Questionnaire!C23 -> Supply chain security | D36: =Questionnaire!D23 -> Is there a list of suppliers with access to systems or data? | E36: =Questionnaire!E23 -> Partial | F36: =Questionnaire!H23 -> 2 | G36: =Questionnaire!I23 -> Medium | H36: =Questionnaire!K23 -> Write the supplier list with what each can access.
A37: 33 | B37: =Questionnaire!A28 -> e2 | C37: =Questionnaire!C28 -> Secure acquisition, development and maintenance | D37: =Questionnaire!D28 -> Are the ERP and web shop kept up to date by their suppliers? | E37: =Questionnaire!E28 -> Partial | F37: =Questionnaire!H28 -> 2 | G37: =Questionnaire!I28 -> Medium | H37: =Questionnaire!K28 -> Ask the web agency for update and vulnerability-handling commitments.
A38: 34 | B38: =Questionnaire!A30 -> e4 | C38: =Questionnaire!C30 -> Secure acquisition, development and maintenance | D38: =Questionnaire!D30 -> Are security requirements considered when buying new systems? | E38: =Questionnaire!E30 -> No | F38: =Questionnaire!H30 -> 2 | G38: =Questionnaire!I30 -> Medium | H38: =Questionnaire!K30 -> Add a few security questions to purchasing.
A39: 35 | B39: =Questionnaire!A33 -> f3 | C39: =Questionnaire!C33 -> Effectiveness assessment | D39: =Questionnaire!D33 -> Are security status or metrics reported to management? | E39: =Questionnaire!E33 -> No | F39: =Questionnaire!H33 -> 2 | G39: =Questionnaire!I33 -> Medium | H39: =Questionnaire!K33 -> Add a short quarterly security update to management meetings.
A40: 36 | B40: =Questionnaire!A37 -> g4 | C40: =Questionnaire!C37 -> Cyber hygiene and training | D40: =Questionnaire!D37 -> Are there password rules (length, no reuse)? | E40: =Questionnaire!E37 -> Partial | F40: =Questionnaire!H37 -> 2 | G40: =Questionnaire!I37 -> Medium | H40: =Questionnaire!K37 -> Set a clear password rule and allow a password manager.
A41: 37 | B41: =Questionnaire!A38 -> h1 | C41: =Questionnaire!C38 -> Cryptography and encryption | D41: =Questionnaire!D38 -> Are laptops encrypted (e.g. BitLocker)? | E41: =Questionnaire!E38 -> Partial | F41: =Questionnaire!H38 -> 2 | G41: =Questionnaire!I38 -> Medium | H41: =Questionnaire!K38 -> Turn on BitLocker on all laptops.
...

Sheet Risk register
A1: Risk register — Kertvár Food Distribution Kft.
A2: Likelihood and impact on a 1–5 scale (yellow cells). Score = likelihood × impact. High ≥ 15 · Medium 8–14 · Low < 8.
A4: ID | B4: Risk | C4: Area | D4: Linked gaps | E4: Cause | F4: Likelihood (1-5) | G4: Impact (1-5) | H4: Score | I4: Rating | J4: Owner | K4: Treatment | L4: Action | M4: Target date | N4: Status
A5: R01 | B5: Ransomware encrypts server and NAS backup together; ERP down for days | C5: c | D5: c2, c3, j1 | E5: Phishing reaches staff; no MFA; backup in same room and online | F5: 4 | G5: 5 | H5: =F5*G5 -> 20 | I5: =IF(H5>=15,"High",IF(H5>=8,"Medium","Low")) -> High | J5: IT administrator | K5: Reduce | L5: Off-site/offline backup copy; quarterly restore test; MFA for all | M5: Q4 2026 | N5: Open
A6: R02 | B6: Microsoft 365 account takeover through phishing; fraudulent invoices sent to customers | C6: j | D6: j1, g2 | E6: No MFA on 98% of accounts; no phishing training | F6: 4 | G6: 4 | H6: =F6*G6 -> 16 | I6: =IF(H6>=15,"High",IF(H6>=8,"Medium","Low")) -> High | J6: IT administrator | K6: Reduce | L6: Enable MFA for all users; phishing awareness training | M6: Q4 2026 | N6: Open
A7: R03 | B7: Significant incident not reported to the CSIRT in time; regulatory sanctions | C7: b | D7: b1, b3 | E7: No incident procedure; reporting duty unknown | F7: 3 | G7: 4 | H7: =F7*G7 -> 12 | I7: =IF(H7>=15,"High",IF(H7>=8,"Medium","Low")) -> Medium | J7: Managing director | K7: Reduce | L7: Incident procedure with named reporter and 24h/72h deadlines | M7: Q4 2026 | N7: Open
A8: R04 | B8: Compromised supplier uses permanent remote access to enter the network | C8: d | D8: d3, j2 | E8: Always-on supplier VPN with password only | F8: 3 | G8: 5 | H8: =F8*G8 -> 15 | I8: =IF(H8>=15,"High",IF(H8>=8,"Medium","Low")) -> High | J8: IT administrator | K8: Reduce | L8: On-request supplier access with MFA and logging | M8: Q1 2027 | N8: Open
A9: R05 | B9: Cold store monitoring hijacked via default password; alarms disabled; stock spoiled | C9: e | D9: e3 | E9: Vendor default password on cloud dashboard | F9: 3 | G9: 4 | H9: =F9*G9 -> 12 | I9: =IF(H9>=15,"High",IF(H9>=8,"Medium","Low")) -> Medium | J9: Warehouse manager | K9: Reduce | L9: Change password now; ask vendor about MFA | M9: Q4 2026 | N9: Open
A10: R06 | B10: Former employee keeps access and misuses data | C10: i | D10: i1, i5 | E10: No leaver checklist; no access reviews | F10: 2 | G10: 3 | H10: =F10*G10 -> 6 | I10: =IF(H10>=15,"High",IF(H10>=8,"Medium","Low")) -> Low | J10: Finance manager | K10: Reduce | L10: Leaver checklist with account removal; half-yearly access review | M10: Q1 2027 | N10: Open
A11: R07 | B11: Shared scanner logins hide who changed stock records | C11: i | D11: i2 | E11: Shared warehouse logins | F11: 3 | G11: 2 | H11: =F11*G11 -> 6 | I11: =IF(H11>=15,"High",IF(H11>=8,"Medium","Low")) -> Low | J11: Warehouse manager | K11: Reduce | L11: Individual scanner logins or PINs | M11: Q2 2027 | N11: Open
A12: R08 | B12: Unpatched server vulnerability exploited | C12: e | D12: e1 | E12: Irregular server patching | F12: 3 | G12: 4 | H12: =F12*G12 -> 12 | I12: =IF(H12>=15,"High",IF(H12>=8,"Medium","Low")) -> Medium | J12: IT administrator | K12: Reduce | L12: Monthly patch window agreed with the MSP | M12: Q4 2026 | N12: Open
A13: R09 | B13: Lost or stolen laptop exposes customer and staff data | C13: h | D13: h1 | E13: Older laptops not encrypted | F13: 3 | G13: 3 | H13: =F13*G13 -> 9 | I13: =IF(H13>=15,"High",IF(H13>=8,"Medium","Low")) -> Medium | J13: IT administrator | K13: Reduce | L13: BitLocker on all laptops | M13: Q1 2027 | N13: Open
A14: R10 | B14: Payroll data leaked when sent by plain email | C14: j | D14: j4 | E14: Payroll files sometimes emailed | F14: 2 | G14: 4 | H14: =F14*G14 -> 8 | I14: =IF(H14>=15,"High",IF(H14>=8,"Medium","Low")) -> Medium | J14: Finance manager | K14: Reduce | L14: Use the payroll bureau's secure portal only | M14: Q4 2026 | N14: Open
A15: R11 | B15: Management held personally liable for missing NIS2 measures | C15: M | D15: M1, M2 | E15: Measures not approved; no management training | F15: 3 | G15: 4 | H15: =F15*G15 -> 12 | I15: =IF(H15>=15,"High",IF(H15>=8,"Medium","Low")) -> Medium | J15: Managing director | K15: Reduce | L15: Approve policy and measures plan; management training | M15: Q4 2026 | N15: Open
A16: R12 | B16: ERP outage stops order taking with no fallback | C16: c | D16: c4, c5 | E16: No manual fallback; no recovery targets | F16: 3 | G16: 3 | H16: =F16*G16 -> 9 | I16: =IF(H16>=15,"High",IF(H16>=8,"Medium","Low")) -> Medium | J16: Managing director | K16: Reduce | L16: Manual fallback procedure; agreed recovery targets | M16: Q1 2027 | N16: Open

Sheet Company
A1: Company profile (fictional)
A3: Name | B3: Kertvár Food Distribution Kft.
A4: Sector | B4: Food — wholesale distribution (NIS2 Annex II)
A5: Staff | B5: 140 (office 35, warehouse 70, drivers 35)
A6: Annual revenue | B6: ~€28 million
A7: Size class | B7: Medium-sized enterprise
A8: NIS2 status | B8: Important entity
A9: What they do | B9: Delivers chilled, frozen and dry food to ~900 restaurants, hotels, school kitchens and shops in Budapest and Pest County.
A10: Location | B10: One site on the southern edge of Budapest: offices, dry warehouse, cold store.
A11: ERP | B11: SAP Business One, run by an outside SAP partner (orders, stock, invoicing, NAV Online Számla).
A12: Server room | B12: One physical server (SAP, file share, domain controller); NAS backup in the same room.
A13: Email and office | B13: Microsoft 365 Business; MFA only for IT admin and managing director.
A14: Devices | B14: ~45 Windows PCs/laptops, 25 warehouse scanners, 35 driver Android phones.
... A18: Key suppliers | B18: SAP partner, IT contractor, refrigeration vendor, web agency, payroll bureau.

Sheet Method
A1: Method and sources
A3: Scoring | B3: Yes = 2, Partial = 1, No = 0, N/A excluded. Area score = points achieved ÷ points possible.
A4: Weight | B4: 1 = useful, 2 = important, 3 = critical. Set per question by the reviewer.
A5: Gap score | B5: (2 − points) × weight. High ≥ 4, Medium 2–3, Low 1.
A6: Area rating | B6: Good ≥ 75%, Partial 50–74%, Weak < 50%.
A7: Risk score | B7: Likelihood (1–5) × impact (1–5). High ≥ 15, Medium 8–14, Low < 8.
A8: Limitations | B8: Self-assessment based on interviews/answers, not evidence testing. Not a legal opinion and not a NIS2 audit.
A9: Source | B9: NIS2 Directive (EU) 2022/2555, Art. 20, 21, 23 — eur-lex.europa.eu
A10: Source | B10: Act LXIX of 2024 on the cybersecurity of Hungary — njt.hu/jogszabaly/en/2024-69-00-00
A11: Source | B11: Decree 418/2024 (detailed security measures, Hungary) — for a deeper control mapping later
A12: Input colours | B12: Yellow cells with blue text are inputs; green text links to another sheet; black is calculated.
